Workbook
Name _____Vo1: #REF!
Name _____Vo1: #REF!
Name _____vo2: #REF!
Name _____vo2: #REF!
Name ____Vo1: #REF!
Name ____Vo1: #REF!
Name ____vo2: #REF!
Name ____vo2: #REF!
Name ___Vo1: #REF!
Name ___Vo1: #REF!
Name ___vo2: #REF!
Name ___vo2: #REF!
Name __M2200: BlankMacro1
Name __M2200: BlankMacro1
Name __Vo1: #REF!
Name __Vo1: #REF!
Name __vo2: #REF!
Name __vo2: #REF!
Name _1: #N/A
Name _10: #N/A
Name _101: #N/A
Name _102: #N/A
Name _103: #N/A
Name _104: #N/A
Name _11: #N/A
Name _12: #N/A
Name _13: #N/A
Name _14: #N/A
Name _15: #N/A
Name _16: #N/A
Name _17: #N/A
Name _18: #N/A
Name _19: #N/A
Name _1S: #N/A
Name _2: #N/A
Name _20: #N/A
Name _21: #N/A
Name _22: #N/A
Name _23: #N/A
Name _24: #N/A
Name _25: #N/A
Name _26: #N/A
Name _27: #N/A
Name _2S: #N/A
Name _3: #N/A
Name _4: #N/A
Name _5: #N/A
Name _6: #N/A
Name _7: #N/A
Name _8: #N/A
Name _9: #N/A
Name _94CH: #REF!
Name _95UNIT: #REF!
Name _A79797: '[2]2011上期無錫物量'!#REF!
Name _gp090277: #REF!
Name _gp090277: #REF!
Name _meta: #REF!
Name _Vo1: #REF!
Name _Vo1: #REF!
Name _vo2: #REF!

Sheet 트랜스포머 구조 (2)
B7: A1
C8: Pin | E8: Winding | F8: Ts | G8: Wire | H8: Wire | I8: Barrier | K8: Ts | L8: Insulation | M8: Ts
C9: - | D9: - | E9: - | F9: - | G9: - | H9: mm | I9: Top | J9: Bottom | K9: - | L9: mm | M9: - | O9: TOP | P9: Option 1 | X9: Bottom Pin | AE9: 031-543-6073
B10: 1 | C10: W1 | D10: DCP | E10: 1→ | F10: 45 | G10: 2UEW | H10: 0.16Φ | I10: 2mm | J10: 2mm | K10: 1 | L10: 12.4 | M10: 1.5 | P10: 2mm (1) | Q10: DCP | W10: 2mm (1)
C11: W3 | D11: DCP | E11: →3 | F11: 45 | G11: 2UEW | H11: 0.16Φ | I11: 2mm | J11: 2mm | K11: 1 | L11: 12.4 | M11: 8 | P11: 2mm (1) | Q11: DCP | W11: 2mm (1)
C12: W4 | D12: IPV24 | E12: 10→11 | F12: 16 | G12: TIW | H12: 0.3Φ | I12: - | J12: 4mm | K12: 1 | L12: 12.4 | M12: 1.5 | P12: IPV24 | V12: 4mm (1)
C13: W5 | D13: PV15 | E13: 6→7 | F13: 10 | G13: TIW | H13: 0.3Φ | I13: 4mm | J13: 4mm | K13: 1 | L13: 12.4 | M13: 1.5 | P13: 4mm (1) | R13: PV15 | V13: 4mm (1)
C14: W6 | D14: NV15 | E14: 5→6 | F14: 10 | G14: TIW | H14: 0.3Φ | I14: 4mm | J14: 4mm | K14: 1 | L14: 12.4 | M14: 1.5 | P14: 4mm (1) | R14: NV15 | V14: 4mm (1)
I18: =90-55 -> 35
O56: TOP, Bottom | Q56: Pri~PV5 | R56: 2mm씩 베리어 했기때문에(총4mm) 규격 3.5mm 이상 만족
Q57: IPV5 | R57: 강화 절연이기 때문에 문제 없음
P60: 강점
AN71: TOP, Bottom | AP71: Pri, IPV5 | AQ71: Pri, IPV5 강화 절연이므로 Top, Bottom 절연 신경 안써도 됨, 단 PV5와 코어 사이즈가 가깝기 때문에 핀에서 문제가 됨
AP72: 따라서 약 2mm 이격하여 다른곳에서 1.5mm 만 확보되면 절연 문제 없게끔 가능
AN75: 강점 | AP75: Pri 베리어 없어도 됨, 다만 3중 절연권선 자체가 비쌀수도 있음

Sheet 부하사양2
D4: 2207-1-0007 12V LDO RLY | H4: =3.3/5 -> 0.66 | I4: =H22*H4 -> 113.256 | J4: =I4+I22 -> 155.256
D8: PFC EC FAN | U8: =G25+O25+S25 -> 7.47
D10: 부품 | G10: PV15(제어탭 | L10: 부품 | O10: NV15 | P10: 부품 | S10: IPV24
G11: PV15 | H11: PV3.3 | I11: PV5(Buck) | J11: PFC12 | K11: LDO12 | S11: IPV24 | T11: IPV10.5 | U11: IPV5
D12: UC3844BD1013TR | G12: 17 | P12: SJE-S-124L (알람 RLY) | S12: =(24/1280)*1000 -> 18.75
D13: M81738FP (Gate Driver) | G13: =1.5*3 -> 4.5 | P13: MC34063EBD-T (LDO) | S13: 2.5
D14: Run | G14: =(16000*110*10^-9)*6*1000 -> 10.56 | P14: IPV24 (외부) | S14: 100
D15: CPU_INV | H15: =130*(3.3/5) -> 85.8 | P15: 더미저항 | S15: =(24/1000)*1000 -> 24
D16: CPU_PFC | H16: =130*(3.3/5) -> 85.8 | P16: IPV10.5(외부) | T16: =(10.5/1000)*1000 -> 10.5
D17: ACS724LLCTR-20AB-T | I17: =14*3 -> 42 | P17: Display | U17: 60
D18: 10-F112VPA015M7-LK88A74 | J18: =(45*10^-9*100000)*1000*3 -> 13.5 | P18: R7FA2L1AB3CFL (IO_CPU) | U18: 15
D19: 1EDI20N12AF | J19: =2*3 -> 6
D20: PFC12 Margin | J20: =5*3 -> 15
D21: HF36F-20/012 (초충 RLY) | K21: =(12/270)*1000*2 -> 88.888889
D22: 합계 [mA] | G22: =SUM(G12:G21) -> 32.06 | H22: =SUM(H12:H21) -> 171.6 | I22: =SUM(I12:I21) -> 42 | J22: =SUM(J12:J21) -> 34.5 | K22: =SUM(K12:K21) -> 88.888889 | L22: 합계 [mA] | O22: =SUM(O12:O21) -> 0 | P22: 합계 [mA] | S22: =SUM(S12:S19) -> 145.25 | T22: =SUM(T12:T19) -> 10.5 | U22: =SUM(U12:U19) -> 75
D23: 총 합계 [mA] | G23: =G22+H22*(3.3/15)+I22*(5/15)+J22*(12/15)+K22*(12/15) -> 182.52311 | L23: 총 합계 [mA] | O23: =SUM(O12:O18) -> 0 | P23: 총 합계 [mA] | S23: =S22+T22*(10.5/24)+U22*(5/24) -> 165.46875
D24: 설계 사양 [mA] | G24: 200 | L24: 설계 사양 [mA] | O24: 10 | P24: 설계 사양 [mA] | S24: 180
D25: 소모전력 [W] | G25: =G24*15/1000 -> 3 | L25: 소모전력 | O25: =O24*15/1000 -> 0.15 | P25: 소모전력 | S25: =S24*24/1000 -> 4.32
H29: =H15+H16 -> 171.6
H30: =H29*3.3/5 -> 113.256 | I30: =H30+42 -> 155.256

Sheet 2안
B3: DCM Flyback Transformer 설계 계산서
B4: Phase A [Input Parameter] | O4: Phase B [Output Parameter]
C6: Input Data | P6: Input Data
C7: Output Data | P7: Output Data
C8: Critical Data Design | P8: Critical Data Design | U8: 32
C11: 항목 | H11: 값 | I11: 단위 | J11: 수식/근거 | P11: 항목 | U11: 값 | V11: 단위 | W11: 수식/근거
B12: Input Spec | C12: Pout | H12: 7.47 | I12: W | J12: - | O12: 턴수비 선정 | P12: Np/Ns 허용범위 (해당값 이하 충족할것) | U12: =(H40-H15)/H17 -> 70 | V12: - | W12: n < (VDS_max - Vin) / (Vout + VD_F) [Vr 전압으로 인해 MOSFET 소손방지]
C13: η | H13: 0.8 | I13: % | J13: - | P13: Np/Ns 허용범위 (해당값 이상 충족할것) | U13: =H15/((H17+H21)*((1/U22)-1)) -> 2.4158506 | V13: - | W13: n > Vin / ((Vout + VD_F) × (1/Duty_on - 1)) [DCM 조건 만족, n↓ CCM에 진입]
C14: Pin | H14: =H12/H13 -> 9.3375 | I14: W | J14: - | P14: Np | U14: 90 | V14: Turn
C15: Vin_Min | H15: 300 | I15: V | J15: - | P15: Ns | U15: 10 | V15: Turn
C16: Vin_Max | H16: 850 | I16: V | J16: - | P16: 턴수비 결정 Np/Ns | U16: =U14/U15 -> 9 | V16: - | W16: Np/Ns
C17: PV15 | H17: 15 | I17: V | J17: - | P17: Vr (Reflected voltage) | U17: =(U14/U15)*(H17+H21) -> 143.1 | V17: V
C18: NV15 | H18: 15 | I18: V | J18: - | P18: V Spike Margin | U18: 200 | V18: V | W18: 마진
C19: IPV24 | H19: 24 | I19: V | J19: - | O19: Lp 선정 | P19: Lp [자기적 관점] | U19: =(H28*U14^2*((H26*10^-6)/(H29*10^-3)))*10^6 -> 1034.8406 | V19: uH | W19: Lp = µ0 × Np² × Ae / Aire gap
C20: Fsw | H20: 60 | I20: kHz | J20: BD7F100HFN Datasheet 참고 | P20: Lp [에너지 관점] | U20: =H15^2*U22^2/(2*H14*H20*1000)*10^6 -> 1034.8406 | V20: uH | W20: Lp = Vin² × D² / (2 × Pin × Fsw)
C21: VD_F | H21: 0.9 | I21: V | J21: 1SS355VMTE-17 Datasheet 참고 | P21: Lp.set | U21: 1050 | V21: uH
C22: Dmax_min | H22: 5 | I22: % | J22: BD7F100HFN Duty 20%~50% 권장 | P22: 1차측 on Duty | U22: =SQRT(2*H14*U19*10^-6*H20*10^3)/H15 -> 0.11350668 | V22: % | W22: D = √(2 × Pin × Lp × Fsw) / Vin
C23: Dmax_max | H23: 50 | I23: % | J23: BD7F100HFN Duty 20%~50% 권장 | P23: 2차측 on Duty | U23: =U22*H15/(U16*(H17+H21)) -> 0.23795949 | V23: % | W23: D × Vin / (n × (Vout + VD_F))
C24: MODE | H24: DCM | I24: - | J24: - | O24: 판정 | P24: DCM 만족 | U24: =IF(U22+U23<=1,"DCM","CCM") -> DCM | V24: -
B25: Core Data | C25: Core | H25: EE2020 | I25: - | P25: Ipeak 전류 | U25: =2*H14/(H15*U22) -> 0.54842589 | V25: A | W25: Ip_pk = 2 × Pin / (Vin × D)
C26: Ae (Effective Cross Section Aera) | H26: 30.5 | I26: mm2 | P26: Ipeak 판정 | U26: =IF(U25<H41,"PASS","FAIL") -> PASS | V26: -
C27: AL_zero (Ungapped Effective Inductance) | H27: 1550 | I27: nH/N^2 | P27: P.set (Lp.set 반영 Pin 검증) | U27: =0.5*U21*10^-6*U25^2*H20*1000 -> 9.474285 | V27: W
C28: u0 | H28: =4*PI()*0.0000001 -> 1.2566371e-06 | I28: H/m | P28: Power 검증 P.set > Pin | U28: =IF(U27>H14,"PASS","FAIL") -> PASS | V28: -
C29: Aire gap | H29: 0.3 | I29: mm | J29: 가공 가능 범위 0.1mm 이상으로 할것 | P29: VDS_Max | U29: =H16+U17+U18 -> 1193.1 | V29: V
C30: AL_g (gapped Effective Inductance)) | H30: =(1/(1/(H27*10^-9) + (10^-4)/(H28*H26*10^-6)))*10^9 -> 307.28964 | I30: nH/N^2 | P30: VDS_판정 | U30: =IF(U29<H40,"PASS","FAIL") -> PASS | V30: -
C31: BM,set (Maximum Flux Density) | H31: 0.3
C32: ΔB(flux density swing) | H32: =U21*10^-6*U25/(U14*H26*10^-6) -> 0.20978039 | O32: Wire | P32: Tab | R32: 결선 | T32: Vo | U32: Iout | V32: Ipk | W32: Irms | X32: Turns | Z32: Secondary Voltage | AB32: Set Dia A | AC32: Cal Dia A | AD32: Set Dia | AE32: 마진
B33: Wire Data | C33: 1차측 Wire 직경 | H33: 0.2 | I33: mm | R33: 시작 | S33: 끝 | T33: [V] | U33: [A] | V33: [A] | W33: [A] | X33: Ns.cal | Y33: Ns.set | Z33: Vo.Cal | AA33: Vrrm.cal | AB33: [mm^2] | AC33: [mm^2] | AD33: [mm] | AE33: [%]
C34: 피복 포함 와이어 직경 | H34: 0.2 | I34: mm | P34: Np | Q34: W1,W2 | R34: 1 | S34: 3 | V34: =2*H14/(H15*U22) -> 0.54842589 | W34: =V34*SQRT($U$22/3) -> 0.10667632 | Y34: =$U$14 -> 90 | AB34: =PI()*(AD34/2)^2 -> 0.020106193 | AC34: =W34/$H$39 -> 0.015239474 | AD34: 0.16 | AE34: =(AB34-AC34)/AC34 -> 0.31934952 | AF34: 2 | AG34: 8
C35: 보빈 높이 | H35: =12.4 -> 12.4 | I35: mm | P35: PV15 | Q35: W4 | R35: 6 | S35: 7 | T35: 15 | U35: =부하사양2!G24/1000 -> 0.2 | V35: =U35*2/$U$23 -> 1.6809584 | W35: =V35*SQRT($U$23/3) -> 0.47342136 | Y35: =$U$15 -> 10 | Z35: =(Y35*$U$17/$U$14)-$H$21 -> 15 | AA35: =$H$16/($U$14/Z35)+H21 -> 142.56667 | AB35: =PI()*(AD35/2)^2 -> 0.070685835 | AC35: =W35/$H$39 -> 0.067631623 | AD35: 0.3 | AE35: =(AB35-AC35)/AC35 -> 0.045159523
C36: 배리어 높이 | H36: 2 | I36: mm | P36: NV15 | Q36: W5 | R36: 5 | S36: 6 | T36: -15 | U36: =부하사양2!O24/1000 -> 0.01 | V36: =U36*2/$U$23 -> 0.084047919 | W36: =V36*SQRT($U$23/3) -> 0.023671068 | X36: =$U$14*(ABS(T36)+$H$21)/$U$17 -> 10 | Y36: 10 | Z36: =(Y36*$U$17/$U$14)-$H$21 -> 15 | AA36: =$H$16/($U$14/Z36)+H22 -> 146.66667 | AB36: =PI()*(AD36/2)^2 -> 0.070685835 | AC36: =W36/$H$39 -> 0.0033815811 | AD36: 0.3 | AE36: =(AB36-AC36)/AC36 -> 19.90319
C37: 권선 가능 높이 | H37: =H35-H36 -> 10.4 | I37: mm | P37: IPV24 | Q37: W3 | R37: 10 | S37: 11 | T37: 24 | U37: =부하사양2!S24/1000 -> 0.18 | V37: =U37*2/$U$23 -> 1.5128625 | W37: =V37*SQRT($U$23/3) -> 0.42607922 | X37: =$U$14*(ABS(T37)+$H$21)/$U$17 -> 15.660377 | Y37: 14 | Z37: =(Y37*$U$17/$U$14)-$H$21 -> 21.36 | AA37: =$H$16/($U$14/Z37)+H23 -> 251.73333 | AB37: =PI()*(AD37/2)^2 -> 0.070685835 | AC37: =W37/$H$39 -> 0.060868461 | AD37: 0.3 | AE37: =(AB37-AC37)/AC37 -> 0.16128836
C38: 최대 가능 턴수 | H38: =H37/(H34) -> 52 | I38: Turn
C39: 전류밀도 | H39: 7 | I39: A/mm2 | J39: 5~7사이, 낮을수록 Margin 설계
B40: MOSFET | C40: VDS_max | H40: 1350 | I40: V | J40: 스위치 정격 1500V, 150V마진 확보
B41: Protect | C41: Ipk_Limit (R_Shunt 2ohm -> 1ohm 변경 필요) | H41: 1 | I41: A | J41: R_Shunt 3203-1-0770 변경 필요
Q42: 100000
Q43: =Q42-16 -> 99984 | T43: 2 | U43: 2
Q44: =Q42-Q43 -> 16
B48: TL431A | C48: 2.495 | D48: =C48*(1+10/10) -> 4.99
...

Sheet 전원 확인
E2: Output
E3: Min | F3: Typ | G3: Max
D4: PV15 | E4: =E15 -> 14.637584 | F4: =F15 -> 15.2195 | G4: =G15 -> 15.817727
D5: PV12 | E5: =E31 -> 11.66624 | F5: =F31 -> 12.119565 | G5: =G31 -> 12.585935
D6: NV15 | E6: =E79 -> -15 | F6: =F79 -> -15 | G6: =G79 -> -15
D7: NV12 | E7: =E88 -> -11.5 | F7: =F88 -> -12 | G7: =G88 -> -12.5
D8: PV5 | E8: =E47 -> 4.7596287 | F8: =F47 -> 5.004375 | G8: =G47 -> 5.2563594
D11: PV15
E12: Min | F12: Typ | G12: Max | H12: Absolute
D13: 필요전압 | E13: - | F13: - | G13: - | H13: 37 | I13: V
D14: 설계전압 | J14: → SMPS Tab에서 공급
D15: 출력전압 | E15: =E22 -> 14.637584 | F15: =F22 -> 15.2195 | G15: =G22 -> 15.817727 | I15: V
D17: KIA431AF-RTF/P
D18: Description | E18: Min | F18: Typ | G18: Max
D19: Vref | E19: 2.44 | F19: 2.495 | G19: 2.55 | H19: V
D20: R1 | E20: =F20*0.99 -> 50490 | F20: 51000 | G20: =F20*1.01 -> 51510 | H20: Ω
D21: R2 | E21: =F21*0.99 -> 9900 | F21: 10000 | G21: =F21*1.01 -> 10100 | H21: Ω
D22: Vout | E22: =(1+(E20/G21))*E19 -> 14.637584 | F22: =(1+(F20/F21))*F19 -> 15.2195 | G22: =(1+(G20/E21))*G19 -> 15.817727 | I22: → VKA = Vref * (1 + (R1 / R2))
D26: PV12
E27: Min | F27: Typ | G27: Max | H27: Absolute
D28: 설계전압 | E28: =E15 -> 14.637584 | F28: =F15 -> 15.2195 | G28: =G15 -> 15.817727
D29: 필요전압 | E29: 3.5 | F29: - | G29: 40 | H29: 42 | I29: V | J29: → Datasheet 사양
D30: 판정 | E30: =IF(E29<E28,"PASS","FAIL") -> PASS | G30: =IF(G29>G28,"PASS","FAIL") -> PASS
D31: 출력전압 | E31: =E38 -> 11.66624 | F31: =F38 -> 12.119565 | G31: =G38 -> 12.585935 | I31: V
D33: AW37283BADJSPR-Q1
D34: Description | E34: Min | F34: Typ | G34: Max
D35: Vref | E35: 1.225 | F35: 1.25 | G35: 1.275 | H35: V
D36: R1 | E36: =F36*0.99 -> 11385 | F36: 11500 | G36: =F36*1.01 -> 11615 | H36: Ω | I36: → 3203-1-0502으로 변경 (11.5kohm) 2026/02/26
D37: R2 | E37: =F37*0.99 -> 99000 | F37: 100000 | G37: =F37*1.01 -> 101000 | H37: Ω
D38: Vout | E38: =(1+(E37/G36))*E35 -> 11.66624 | F38: =(1+(F37/F36))*F35 -> 12.119565 | G38: =(1+(G37/E36))*G35 -> 12.585935 | I38: → Vout = 1.25V * (1 + (R2 / R1))
D42: PV5
E43: Min | F43: Typ | G43: Max | H43: Absolute
D44: 설계 Input | E44: =E15 -> 14.637584 | F44: =F15 -> 15.2195 | G44: =G15 -> 15.817727 | I44: V
D45: Vcc Input | E45: 4 | F45: - | G45: 60 | H45: 65 | I45: V | J45: → Datasheet 사양
D46: 판정 | E46: =IF(E45<E44,"PASS","FAIL") -> PASS | G46: =IF(G45>G44,"PASS","FAIL") -> PASS
D47: 출력전압 | E47: =F66 -> 4.7596287 | F47: =G66 -> 5.004375 | G47: =H66 -> 5.2563594 | I47: V
M52: KIA1117BF33RTF
M53: Description | R53: Min | S53: Typ | T53: Max
M54: Input Voltage Range | Q54: VIN | T54: 15 | U54: V
M55: Vout | Q55: Vout | R55: 3.201 | S55: 3.3 | T55: 3.399 | U55: V
...

Sheet 수명
C2: 내부온도 | D2: 85 | E2: ℃
D4: 용량 | E4: WV | F4: V | G4: Lo | H4: To | I4: T | J4: 계산수명 | K4: 년수 | L4: 측정온도 | M4: 사이즈 | N4: 비고 | O4: ERP
D5: uF | E5: V | F5: V | G5: Hr | H5: ℃ | I5: ℃ | J5: 10000 Hr | K5: Years
B6: 변경전 | C6: PV3.3 | D6: 47 | E6: 25 | F6: 3.3 | G6: 2000 | H6: 105 | I6: =$D$2 -> 85 | J6: =(G6*2^((H6-I6)/10)/10000) -> 0.8 | K6: =J6*10000/(365*24) -> 0.91324201 | N6: CP1,CP2 | O6: 1003-1-0011 | P6: BXJ 47uF,25V,EL | Q6: C,EL,47uF,D6.3/6.6/6.6/5.7,,25V,105/1000 | R6: KRW | S6: 34 | T6: =S6 * IF(R6=$G$4,$L$4, IF(R6=$G$6,$L$6, IF(R6=$G$7, $L$7, 1) ) ) -> 34 | U6: SAMYOUNG
C7: PV15 | D7: 470 | E7: 25 | F7: 15 | G7: 4000 | H7: 105 | I7: =$D$2 -> 85 | J7: =(G7*2^((H7-I7)/10)/10000) -> 1.6 | K7: =J7*10000/(365*24) -> 1.826484 | M7: D10/L12.5 | N7: CP5 | O7: 1003-2-0026 | P7: NXB25VB470M | Q7: C,EL,470uF,RAD,20%,25V,105/ | R7: KRW | S7: 65 | T7: =S7 * IF(R7=$G$4,$L$4, IF(R7=$G$6,$L$6, IF(R7=$G$7, $L$7, 1) ) ) -> 65 | U7: SAMYOUNG
C8: NV15 | D8: 100 | E8: 25 | F8: 15 | G8: 10000 | H8: 105 | I8: =$D$2 -> 85 | J8: =(G8*2^((H8-I8)/10)/10000) -> 4 | K8: =J8*10000/(365*24) -> 4.56621 | M8: D6.3/D11 | N8: CP4 | O8: 1003-2-0269 | P8: ZLU025M101E11CSR | R8: USD | S8: 0.0136 | T8: 19.312 | U8: MEC
C9: IPV24 | D9: 270 | E9: 35 | F9: 24 | G9: 10000 | H9: 105 | I9: =$D$2 -> 85 | J9: =(G9*2^((H9-I9)/10)/10000) -> 4 | K9: =J9*10000/(365*24) -> 4.56621 | M9: D8/L20 | N9: CP3 | O9: 1003-2-0270 | P9: ZLU035M271F20CSR | R9: USD | S9: 0.0382 | T9: 54.244 | U9: MEC
C10: Vcc | D10: 56 | E10: 50 | F10: 15 | G10: 6000 | H10: 105 | I10: =$D$2 -> 85 | J10: =(G10*2^((H10-I10)/10)/10000) -> 2.4 | K10: =J10*10000/(365*24) -> 2.739726 | M10: D6.3/D11 | N10: CP6 | O10: 1003-2-0271 | P10: UZT050M560E11CSR | R10: USD | S10: 0.0161 | T10: 22.862
B11: 변경후 | C11: PV3.3 | D11: 22 | E11: 25 | F11: 3.3 | G11: - | H11: - | I11: =$D$2 -> 85 | J11: - | K11: - | L11: - | M11: 3225 | N11: CP1,CP2 | O11: 1002-1-0166 | P11: GRM32ER71E226ME15L | Q11: C,CC,22uF,3225,20%,25V,X7R | R11: KRW | S11: 170 | T11: =S11 * IF(R11=$F$2,$G$2, IF(R11=$F$3,$G$3, IF(R11=$F$4, $G$4, 1) ) ) -> 170
C12: PV15 | D12: 270 | E12: 35 | F12: 24 | G12: 10000 | H12: 105 | I12: =$D$2 -> 85 | J12: =(G12*2^((H12-I12)/10)/10000) -> 4 | K12: =J12*10000/(365*24) -> 4.56621 | M12: D8/L20 | N12: CP5 | O12: 1003-2-0270 | P12: ZLU035M271F20CSR | R12: USD | S12: 0.0382 | T12: 54.244 | U12: MEC
C13: NV15 | D13: 100 | E13: 25 | F13: 15 | G13: 10000 | H13: 105 | I13: =$D$2 -> 85 | J13: =(G13*2^((H13-I13)/10)/10000) -> 4 | K13: =J13*10000/(365*24) -> 4.56621 | M13: D6.3/D11 | N13: CP4 | O13: 1003-2-0269 | P13: ZLU025M101E11CSR | R13: USD | S13: 0.0136 | T13: 19.312 | U13: MEC
C14: IPV24 | D14: 270 | E14: 35 | F14: 24 | G14: 10000 | H14: 105 | I14: =$D$2 -> 85 | J14: =(G14*2^((H14-I14)/10)/10000) -> 4 | K14: =J14*10000/(365*24) -> 4.56621 | M14: D8/L20 | N14: CP3 | O14: 1003-2-0270 | P14: ZLU035M271F20CSR | R14: USD | S14: 0.0382 | T14: 54.244 | U14: MEC
C15: Vcc | D15: 56 | E15: 50 | F15: 15 | G15: 10000 | H15: 105 | I15: =$D$2 -> 85 | J15: =(G15*2^((H15-I15)/10)/10000) -> 4 | K15: =J15*10000/(365*24) -> 4.56621 | M15: D6.3/D11 | N15: CP6 | O15: NEW | P15: ZLU035M560E11CSR | Q15: C,CC,56uF/D6.3/D11,20%,35V,105/10000 | R15: ? | S15: ? | T15: ?
T18: =SUM(#REF!) -> #REF!
O20: 1003-2-0271 | P20: UZT050M560E11CSR | R20: USD | S20: 0.0161 | T20: 22.862
O21: 1003-2-0287 | P21: UZT035M151F12TP3R | Q21: C,EL,150uF,RAD,20%,35V,105/8x11.5/8000h | R21: USD | S21: 0.037 | T21: 52.54
O22: 1003-2-0286 | P22: UZT035M102X20TP5R | Q22: C,EL,1000uF,RAD,20%,35V,105/12.5x20/10000h | R22: USD | S22: 0.1151 | T22: 163.442
O23: 1003-2-0285 | P23: UZT016M331E15TP2R | Q23: C,EL,330uF,RAD,20%,16V,105/6.3x15/6000h | R23: USD | S23: 0.0258 | T23: 36.636
O24: 1003-2-0284 | P24: UZT025M221E15TP2R | Q24: C,EL,220uF,RAD,20%,25V,105/6.3x15/6000h | R24: USD | S24: 0.034 | T24: 48.28
O25: 1003-2-0283 | P25: UZT010M102F15TP3R | Q25: C,EL,1000uF,RAD,20%,10V,105/8x15/8000h | R25: USD | S25: 0.0361 | T25: 51.262
O26: 1003-2-0282 | P26: UZT035M101E11TP2R | Q26: C,EL,100uF,RAD,20%,35V,105/6.3x11/6000h | R26: USD | S26: 0.0212 | T26: 30.104
O28: 1003-2-0268 | P28: ZLU010M681F16CSR | R28: USD | S28: 0.0313 | T28: 44.446
O29: 1003-2-0269 | P29: ZLU025M101E11CSR | Q29: C,EL,100uF, | R29: USD | S29: 0.0136 | T29: 19.312
O30: 1003-2-0270 | P30: ZLU035M271F20CSR | R30: USD | S30: 0.0382 | T30: 54.244
O31: 1003-2-0272 | P31: ZLU050M100D11CSR | R31: USD | S31: 0.0087 | T31: 12.354
O32: 1003-2-0242 | P32: NXH50VB470M | Q32: C,EL,470uF,D10/L33,20%,50V,105/10000 | R32: KRW | S32: 189 | T32: 189
O33: 1003-2-0241 | P33: NXH50VB820M | Q33: C,EL,820uF,D12.5/L35,20%,50V,105/10000 | R33: KRW | S33: 230 | T33: 230
O34: 1003-2-0273 | P34: NXH25VB820M | Q34: C,EL,820UF,D10/L20/RAD,20%,25V,105/10000 | R34: KRW | S34: 85 | T34: 85
O36: 1003-2-0075 | P36: NXH35VB270M | Q36: C,EL,270uF,D8/L15/RAD,20%,35V,105/8000 | R36: KRW | S36: 77 | T36: 77
O37: 1003-2-0076 | P37: NXH25VB100M | Q37: C,EL,100uF,D6.3/L11/RAD,20%,25V,105/8000 | R37: KRW | S37: 44 | T37: 44
O38: 1003-2-0077 | P38: NXH10VB680M | Q38: C,EL,680uF,D8/L11.5/RAD,20%,10V,105/8000 | R38: KRW | S38: 67 | T38: 67
O39: 1003-2-0078 | P39: NXH50VB10M | Q39: C,EL,10uF,D5/L11/RAD,20%,50V,105/8000 | R39: KRW | S39: 34 | T39: 34
O40: 1003-2-0097 | P40: NXH50VB120M | Q40: C,EL,120uF,D8/L15/RAD,20%,50V,105/8000 | R40: KRW | S40: 64.5 | T40: 64.5
O41: 1003-2-0163 | P41: NXH 25VB 330M (8X11.5) | Q41: C,EL,330uF,8D/11.5L/RAD,20%,25V,105/8000 | R41: KRW | S41: 58.6 | T41: 58.6
O42: 1003-2-0207 | P42: NXH10VB1000M | Q42: C,EL,1000UF,D8/L15,20%,10V,105/8000 | R42: KRW | S42: 68 | T42: 68
O43: 1003-2-0239 | P43: 35ZLH270M 8X16 | Q43: C,EL,270uF,D8/H16,35V,105/8000 | R43: USD | S43: 0.081 | T43: 115.02
O44: 1003-2-0240 | P44: 10ZLH680M 8X11.5 | Q44: C,EL,680uF,D8/H11.5,10V,105/8000 | R44: USD | S44: 0.0699 | T44: 99.258
O45: CP02-3-0339 | P45: BLA 47uF,25V,EL | Q45: BLA 47uF,25V,EL | R45: KRW | S45: 150 | T45: =S45 * IF(R45=$G$4,$L$4, IF(R45=$G$6,$L$6, IF(R45=$G$7, $L$7, 1) ) ) -> 150
O46: 1003-1-0018 | P46: BLA 47uF,25V,EL | Q46: C,EL,47uF,D6.3/L6,25V,105/5000 | R46: KRW | S46: 150 | T46: =S46 * IF(R46=$G$4,$L$4, IF(R46=$G$6,$L$6, IF(R46=$G$7, $L$7, 1) ) ) -> 150
O47: 1003-2-0277 | P47: NXH25VB47M | Q47: C,EL,47UF,D5/L11/RAD,20%,25V,105/7000 | R47: KRW | S47: 24 | T47: =S47 * IF(R47=$G$4,$L$4, IF(R47=$G$6,$L$6, IF(R47=$G$7, $L$7, 1) ) ) -> 24
...

Sheet 주변회로

Sheet Start up
C2: 1. 개요
C3: - 효성향 SMPS 의 보호회로 설계기준을 검토
C5: 2. 요구 사양
C6: - UC3844 UVLO 사양 검토 확인
C7: - 3초 이내 기동 준비 완료
C9: 3. Design
C32: 사양 검토 확인
C33: UC3844 Dataseet | I33: Min | J33: Typ | K33: Max
E34: Start Threshold | I34: 14.5 | J34: 16 | K34: 17.5 | L34: V
E35: Min Operating Voltage | I35: 8.5 | J35: 10 | K35: 11.5 | L35: V
E36: Operating Supply Current | J36: 12 | K36: 17 | L36: mA
E37: Start-up current | J37: 0.3 | K37: 0.5 | L37: mA
O38: `
C40: Start-up Voltage 확인 | I40: Min | J40: Typ | K40: Max
E41: R145,R182 | I41: =J41*0.99 -> 396 | J41: 400 | K41: =J41*1.01 -> 404 | L41: kΩ | M41: → 200kohm → 400kohm으로 변경 (온도 이슈 있었음) 아래 열화상 카메라 사진 참고
E42: Start-up Voltage | I42: =J37*I41*2 -> 237.6 | J42: =J37*J41*2 -> 240 | K42: =K37*K41*2 -> 404 | L42: V | M42: → 최대 404V 에서 전원 동작
E43: DC Link 범위 | I43: =380*0.9*SQRT(2) -> 483.66104 | J43: 700 | K43: 850 | L43: V | M43: → 최소치 : 480V [380*0.9*sqrt(2)], DC Link 기본 제어 전압 : 700V, 최대 전압 : 850V [810(OV Level)+40(Margin)]
E44: 판정 | I44: =IF(K42<I43,"PASS","FAIL") -> PASS | M44: → Start-up Voltage < DC Link max [Ture = PASS]
C46: Start up 기동시간 | I46: Min | J46: Typ | K46: Max
E47: 전해커패시터 용량 | I47: =J47*0.8 -> 44.8 | J47: 56 | K47: =J47*1.2 -> 67.2 | L47: uF
E48: DC Link 범위 | I48: =380*0.9*SQRT(2) -> 483.66104 | J48: =380*SQRT(2) -> 537.40115 | K48: =380*1.1*SQRT(2) -> 591.14127 | L48: V
E49: Start up Current | I49: =I48/(K41*2) -> 0.59859039 | J49: =J48/(J41*2) -> 0.67175144 | K49: =K48/(I41*2) -> 0.74639049 | L49: mA
E50: Start up Time | I50: =I47*10^-6*I34/(K49*0.001) -> 0.87032191 | J50: =J47*10^-6*J34/(J49*0.001) -> 1.3338267 | K50: =K47*10^-6*K34/(I49*0.001) -> 1.9646156 | L50: s | M50: → 최대 약 2s 소요예상
E51: 판정 | I51: =IF(K50<3,"PASS","FAIL") -> PASS
C53: UC3844 충전저항 소모전력 | I53: Min | J53: Typ | K53: Max
E54: PV15 탭전압 | I54: ='전원 확인'!E15 -> 14.637584 | J54: ='전원 확인'!F15 -> 15.2195 | K54: ='전원 확인'!G15 -> 15.817727 | L54: V
E55: KDS226-RTK VF 전압 | I55: =0.62 -> 0.62 | J55: =0.77 -> 0.77 | K55: =0.8 -> 0.8 | L55: V
E56: R165 | I56: =J56*0.95 -> 95 | J56: 100 | K56: =J56*1.05 -> 105 | L56: Ω
E57: Vcc 공급 전압 | I57: =I54-K55-(K70/1000*K56) -> 11.956927 | J57: =J54-J55 -> 14.4495 | K57: =K54-I55-(K70/1000*I56) -> 13.496181 | L57: V | M57: → Vcc Min 전압이 충전 저항 소모전력 측면에서 악조건
E58: R145,R182 예상 전압 | I58: =(I43-I57)/2 -> 235.85206 | J58: =(J43-J57)/2 -> 342.77525 | K58: =(K43-K57)/2 -> 418.25191 | L58: V
E59: Vcc 전류 | K59: =(K58*2)/(I41*2) -> 1.0561917 | L59: mA
E60: Vcc 전력 | K60: =(K59*0.001)^2*I41*1000 -> 0.44175419 | L60: W | M60: → 최대 0.44W 소모 예상
E61: 저항 Rated Power | K61: 2 | L61: W | AB61: =K71*0.001*100 -> 1.7312427
E62: 저항 120℃ Rated Power | K62: =2*0.4 -> 0.8 | L62: W
E63: 판정 | I63: =IF(K60<K62,"PASS","FAIL") -> PASS | L63: W
AB65: 2.5
C66: t_hold-up (방전시간 기준) | I66: Min | J66: Typ | K66: Max
E67: Qg (RTK3N150T7) | J67: 15 | L67: nC | AB67: =AB65-AB61 -> 0.76875734
E68: fsw (UC3844) | J68: =1.72/(3000*4.72*10^-9)/2/1000 -> 60.734463 | L68: kHz
E69: Ig_gate | J69: =J67*10^-9*J68*10^3*1000 -> 0.91101695 | L69: mA
...

Sheet Start up 검증
B3: 3. Design

Sheet Sheet1
A1: RSS 공차 분석 방법론 (Vout 출력전압 오차 계산)
A3: 1. RSS (Root Sum Square) 개념
A4: - 각 오차 소스가 독립적·랜덤하게 발생한다는 통계적 가정
A5: - 모든 오차가 동시에 같은 방향으로 발생하는 WC(Worst Case)는 비현실적
A6: - RSS = √( err₁² + err₂² + ... + errₙ² )
A7: - 적용 조건: 각 오차 소스가 서로 독립적이어야 함 (상관관계 없음)
A9: 2. Vout 오차 소스 분류
A10: Vout = Vref × (1 + R1 / R2) ← LDO/Buck 공통 구조
A12: 오차 소스 | B12: 구분 | C12: 오차 처리 | D12: 사유
A13: Vref | B13: IC 내부 | C13: WC 그대로 | D13: 밴드갭 기준전압, 독립 분해 불가
A14: R1 | B14: 외부 부품 | C14: RSS 적용 | D14: 독립 부품, 오차 랜덤 → RSS 가정 성립
A15: R2 | B15: 외부 부품 | C15: RSS 적용 | D15: 독립 부품, 오차 랜덤 → RSS 가정 성립
A17: 3. 실무 적용 수식 (Vref WC + R비율 RSS)
A19: Step 1) R1/R2 비율의 RSS 오차 계산
A20: R_RSS = √( R1_tol² + R2_tol² )
A21: 예) R1 ±1%, R2 ±1% → R_RSS = √(0.01² + 0.01²) = 1.41%
A23: Step 2) Vout Min/Max 계산
A24: Vout_Min = Vref_Min × ( 1 + R1/R2_Typ × (1 - R_RSS) )
A25: Vout_Max = Vref_Max × ( 1 + R1/R2_Typ × (1 + R_RSS) )
A27: ※ Vref는 WC 값(Min/Max) 그대로 적용, R1/R2 비율만 RSS 합성
A29: 4. 계산 예시 (LV2862XLVDDCR, PV5)
A30: 조건: Vref = 0.740 / 0.765 / 0.790V, R1 = 6650Ω ±1%, R2 = 1200Ω ±1%
A32: R_RSS = √(0.01² + 0.01²) = 0.01414 (1.41%)
A33: R1/R2_Typ = 6650 / 1200 = 5.5417
... A38: 5. 방식 비교
A40: 방식 | B40: Min (V) | C40: Max (V) | D40: 폭 (V) | E40: 비고
A41: WC (최악) | B41: 4.76 | C41: 5.256 | D41: 0.497 | E41: 모든 오차 동시 최대
A42: RSS 실무 (Vref WC + R RSS) | B42: 4.783 | C42: 5.23 | D42: 0.447 | E42: ★ 권장 (WC 대비 약 10% 좌)
A43: Full RSS (전체) | B43: 4.83 | C43: 5.179 | D43: 0.348 | E43: Vref도 RSS 적용 (남관적)
A45: ※ 핵심: Vref는 IC 내부 밴드갭 기준전압으로 독립 분해 불가 → 데이터시트 WC 그대로 적용
A46: ※ R1, R2는 독립 외부 부품으로 오차가 랜덤 → RSS 가정 성립 → R1/R2 비율만 RSS 합성
A47: ※ 참조: '전원 확인' 시트 E66:H67 (Vout WC / RSS 계산표)
